<testsuite name="Django Project Tests" errors="1" failures="2" skips="0" tests="23" time="11.300"><testcase time="0.625409" classname="tests.test_views.TestViews" name="test_reports_view_GET" /><testcase time="0.587316" classname="tests.test_views.TestViews" name="test_reports_view_POST" /><testcase time="0.000000" classname="trials.tests.test_forms.TestForms" name="test_grower_form_no_data" /><testcase time="0.057999" classname="trials.tests.test_forms.TestForms" name="test_grower_form_valid_data" /><testcase time="0.000000" classname="trials.tests.test_forms.TestForms" name="test_measurement_form_no_data" /><testcase time="0.001000" classname="trials.tests.test_forms.TestForms" name="test_measurement_form_valid_data" /><testcase time="0.000000" classname="trials.tests.test_forms.TestForms" name="test_product_form_no_data" /><testcase time="0.059000" classname="trials.tests.test_forms.TestForms" name="test_products_form_valid_data"><failure type="builtins.AssertionError" message="False is not true">Traceback (most recent call last):
  File "C:\Users\Luther\Documents\CS_4360\SeedApp\SeedApp\trials\tests\test_forms.py", line 34, in test_products_form_valid_data
    self.assertTrue(form.is_valid())
AssertionError: False is not true
</failure></testcase><testcase time="0.000000" classname="trials.tests.test_forms.TestForms" name="test_trial_form_no_data" /><testcase time="0.059008" classname="trials.tests.test_forms.TestForms" name="test_trial_form_valid_data"><failure type="builtins.AssertionError" message="False is not true">Traceback (most recent call last):
  File "C:\Users\Luther\Documents\CS_4360\SeedApp\SeedApp\trials\tests\test_forms.py", line 17, in test_trial_form_valid_data
    self.assertTrue(form.is_valid())
AssertionError: False is not true
</failure></testcase><testcase time="0.228930" classname="trials.tests.test_models.TestModels" name="test_grower_creation" /><testcase time="0.217628" classname="trials.tests.test_models.TestModels" name="test_measure_creation" /><testcase time="0.240000" classname="trials.tests.test_models.TestModels" name="test_product_creation" /><testcase time="0.257064" classname="trials.tests.test_models.TestModels" name="test_trial_creation" /><testcase time="0.016000" classname="trials.tests.test_views.TestViews" name="test_project_home_GET" /><testcase time="0.067000" classname="trials.tests.test_views.TestViews" name="test_project_measurement_GET" /><testcase time="0.478783" classname="trials.tests.test_views.TestViews" name="test_project_products_GET" /><testcase time="0.353000" classname="trials.tests.test_views.TestViews" name="test_project_trials_GET" /><testcase time="0.001000" classname="trials.tests.test_urls.TestUrls" name="test_dashboard_url_is_resolves" /><testcase time="0.001001" classname="trials.tests.test_urls.TestUrls" name="test_measurements_url_is_resolves" /><testcase time="0.001001" classname="trials.tests.test_urls.TestUrls" name="test_products_url_is_resolves" /><testcase time="0.000998" classname="trials.tests.test_urls.TestUrls" name="test_trials_url_is_resolves" /><testcase time="0.000000" classname="unittest.loader._FailedTest" name="rigister"><error type="builtins.ImportError" message="Failed to import test module: rigister&#10;Traceback (most recent call last):&#10;  File &quot;C:\Python39\lib\unittest\loader.py&quot;, line 154, in loadTestsFromName&#10;    module = __import__(module_name)&#10;ModuleNotFoundError: No module named 'rigister'&#10;">ImportError: Failed to import test module: rigister
Traceback (most recent call last):
  File "C:\Python39\lib\unittest\loader.py", line 154, in loadTestsFromName
    module = __import__(module_name)
ModuleNotFoundError: No module named 'rigister'

</error></testcase></testsuite>