<testsuite name="Django Project Tests" errors="1" failures="0" skips="0" tests="1" time="1.184"><testcase time="0.301004" classname="tests.LogInTest" name="test_login"><error type="builtins.KeyError" message="'user'">Traceback (most recent call last):
  File "C:\Users\Luther\Documents\CS_4360\SeedApp\SeedApp\register\tests.py", line 15, in test_login
    self.assertTrue(response.context['user'].is_active)
  File "C:\Python39\lib\site-packages\django\template\context.py", line 83, in __getitem__
    raise KeyError(key)
KeyError: 'user'
</error></testcase></testsuite>