<testsuite name="Django Project Tests" errors="1" failures="3" skips="0" tests="22" time="15.488"><testcase time="0.000000" classname="trials.tests.test_forms.TestForms" name="test_grower_form_no_data" /><testcase time="0.060724" classname="trials.tests.test_forms.TestForms" name="test_grower_form_valid_data" /><testcase time="0.000999" classname="trials.tests.test_forms.TestForms" name="test_measurement_form_no_data" /><testcase time="0.000000" classname="trials.tests.test_forms.TestForms" name="test_measurement_form_valid_data" /><testcase time="0.000000" classname="trials.tests.test_forms.TestForms" name="test_product_form_no_data" /><testcase time="0.055000" classname="trials.tests.test_forms.TestForms" name="test_products_form_valid_data"><failure type="builtins.AssertionError" message="False is not true">Traceback (most recent call last):
  File "C:\Users\Luther\Documents\CS_4360\SeedApp\SeedApp\trials\tests\test_forms.py", line 33, in test_products_form_valid_data
    self.assertTrue(form.is_valid())
AssertionError: False is not true
</failure></testcase><testcase time="0.000000" classname="trials.tests.test_forms.TestForms" name="test_trial_form_no_data"><failure type="builtins.AssertionError" message="5 != 4">Traceback (most recent call last):
  File "C:\Users\Luther\Documents\CS_4360\SeedApp\SeedApp\trials\tests\test_forms.py", line 22, in test_trial_form_no_data
    self.assertEquals(len(form.errors), 4)
AssertionError: 5 != 4
</failure></testcase><testcase time="0.119001" classname="trials.tests.test_forms.TestForms" name="test_trial_form_valid_data"><failure type="builtins.AssertionError" message="False is not true">Traceback (most recent call last):
  File "C:\Users\Luther\Documents\CS_4360\SeedApp\SeedApp\trials\tests\test_forms.py", line 16, in test_trial_form_valid_data
    self.assertTrue(form.is_valid())
AssertionError: False is not true
</failure></testcase><testcase time="0.219837" classname="trials.tests.test_models.TestModels" name="test_grower_creation" /><testcase time="0.344001" classname="trials.tests.test_models.TestModels" name="test_measure_creation" /><testcase time="0.255228" classname="trials.tests.test_models.TestModels" name="test_product_creation" /><testcase time="1.003662" classname="trials.tests.test_models.TestModels" name="test_trial_creation" /><testcase time="1.030145" classname="trials.tests.test_views.TestViews" name="test_measurements_POST_add_new_measurements"><error type="django.core.exceptions.ValidationError" message="['ManagementForm data is missing or has been tampered with']">Traceback (most recent call last):
  File "C:\Users\Luther\Documents\CS_4360\SeedApp\SeedApp\trials\tests\test_views.py", line 100, in test_measurements_POST_add_new_measurements
    response = self.client.post(self.measurements_url, {
  File "C:\Python39\lib\site-packages\django\test\client.py", line 748, in post
    response = super().post(path, data=data, content_type=content_type, secure=secure, **extra)
  File "C:\Python39\lib\site-packages\django\test\client.py", line 404, in post
    return self.generic('POST', path, post_data, content_type,
  File "C:\Python39\lib\site-packages\django\test\client.py", line 470, in generic
    return self.request(**r)
  File "C:\Python39\lib\site-packages\django\test\client.py", line 716, in request
    self.check_exception(response)
  File "C:\Python39\lib\site-packages\django\test\client.py", line 577, in check_exception
    raise exc_value
  File "C:\Python39\lib\site-packages\django\core\handlers\exception.py", line 47, in inner
    response = get_response(request)
  File "C:\Python39\lib\site-packages\django\core\handlers\base.py", line 181, in _get_response
    response = wrapped_callback(request, *callback_args, **callback_kwargs)
  File "C:\Users\Luther\Documents\CS_4360\SeedApp\SeedApp\trials\views.py", line 85, in measurements
    if formset.is_valid():
  File "C:\Python39\lib\site-packages\django\forms\formsets.py", line 308, in is_valid
    self.errors
  File "C:\Python39\lib\site-packages\django\forms\formsets.py", line 288, in errors
    self.full_clean()
  File "C:\Python39\lib\site-packages\django\forms\formsets.py", line 329, in full_clean
    for i in range(0, self.total_form_count()):
  File "C:\Python39\lib\site-packages\django\forms\formsets.py", line 112, in total_form_count
    return min(self.management_form.cleaned_data[TOTAL_FORM_COUNT], self.absolute_max)
  File "C:\Python39\lib\site-packages\django\utils\functional.py", line 48, in __get__
    res = instance.__dict__[self.name] = self.func(instance)
  File "C:\Python39\lib\site-packages\django\forms\formsets.py", line 92, in management_form
    raise ValidationError(
django.core.exceptions.ValidationError: ['ManagementForm data is missing or has been tampered with']
</error></testcase><testcase time="0.129005" classname="trials.tests.test_views.TestViews" name="test_project_home_GET" /><testcase time="0.188999" classname="trials.tests.test_views.TestViews" name="test_project_measurement_GET" /><testcase time="0.579312" classname="trials.tests.test_views.TestViews" name="test_project_products_GET" /><testcase time="0.468388" classname="trials.tests.test_views.TestViews" name="test_project_trials_GET" /><testcase time="0.621001" classname="trials.tests.test_views.TestViews" name="test_project_trials_POST_add_new_trial" /><testcase time="0.000000" classname="trials.tests.test_urls.TestUrls" name="test_dashboard_url_is_resolves" /><testcase time="0.001003" classname="trials.tests.test_urls.TestUrls" name="test_measurements_url_is_resolves" /><testcase time="0.000998" classname="trials.tests.test_urls.TestUrls" name="test_products_url_is_resolves" /><testcase time="0.000999" classname="trials.tests.test_urls.TestUrls" name="test_trials_url_is_resolves" /></testsuite>